<?xml version="1.0"?>
<robot xmlns:xacro="http://www.ros.org/wiki/xacro" name="2dlidar_sim">
    <!--Macros-->
    <xacro:include filename="macros.xacro"/>
    <!--drive control-->
    <xacro:include filename="diff_drive.xacro"/>
    <!--Color-->
    <material name="white">
        <color rgba="1 1 1 1"/>
    </material>
    <!--Color-->
    <material name="black">
        <color rgba="0 0 0 1"/>
    </material>
    <!--Color-->
    <material name="blue">
        <color rgba="0 0 1 1"/>
    </material>
    <!--Color-->
    <material name="red">
        <color rgba="1 0 0 1"/>
    </material>
    <!--Color-->
    <material name="green">
        <color rgba = "0 1 0 1"/>
    </material>

    <!--Base Link-->
    <link name="base_link">
    </link>

    <!--Body Link-->
    <joint name="body_joint" type="fixed">
        <origin xyz="0.0 0.0 0.0"/>
        <parent link="base_link"/>
        <child link="body"/>
    </joint>

    <link name="body">
        <visual name="">
            <origin xyz="0.0 0.0 0.05"/>
            <geometry>
                <box size="0.4 0.2 0.15"/>
            </geometry>
            <material name="green"/>
        </visual>
        <collision>
            <origin xyz="0.0 0.0 0.05"/>
            <geometry>
                <box size="0.4 0.2 0.15"/>
            </geometry>
        </collision>
        <xacro:inertial_box mass="1.2" x="0.4" y="0.2" z="0.15">
            <origin xyz="0.0 0.0 0.05" rpy="0 0 0"/>
        </xacro:inertial_box>
    </link>

    <gazebo reference="body">
        <material>
            Gazebo/Green
        </material>
    </gazebo>

    <!--Left, Back Wheel Link-->
    <joint name="left_back_wheel_joint" type="continuous">
        <origin xyz="-0.1 0.1 0.0" rpy="-${pi/2} 0.0 0.0"/>
        <parent link="base_link"/>
        <child link="left_back_wheel"/>
        <axis xyz="0.0 0.0 1.0"/>
        <limit effort="10000" velocity="1000"/>
        <dynamcis damping="1.0" friction="1.0"/>
    </joint>

    <link name="left_back_wheel">
        <visual>
            <geometry>
                <cylinder radius="0.05" length="0.04"/>
            </geometry>
            <material name="white"/>
        </visual>
        <collision>
           <geometry>
                <cylinder radius="0.05" length="0.04"/>
           </geometry>
        </collision>
        <xacro:inertial_cylinder mass="0.4" length="0.04" radius="0.05">
            <origin xyz="0 0 0" rpy="0 0 0"/>
        </xacro:inertial_cylinder>
    </link>

    <gazebo reference="left_back_wheel">
        <material>
            Gazebo/White
        </material>
        <!--mu1 = 주축 방향 마찰계수, 직진 및 후진에 영향 -->
        <!--mu2 = 주축의 수직 방향 마찰계수, 회전에 영향 -->
        <!--mu1>0.5</mu1-->
        <!--mu2>0.1</mu2-->
    </gazebo>

    <!--Right, Back Wheel Link-->
    <joint name="right_back_wheel_joint" type="continuous">
        <origin xyz="-0.1 -0.1 0.0" rpy="-${pi/2} 0.0 0.0"/>
        <parent link="base_link"/>
        <child link="right_back_wheel"/>
        <axis xyz="0.0 0.0 1.0"/>
        <limit effort="10000" velocity="1000"/>
        <dynamcis damping="1.0" friction="1.0"/>
    </joint>

    <link name="right_back_wheel">
        <visual>
            <geometry>
                <cylinder radius="0.05" length="0.04"/>
            </geometry>
            <material name="white"/>
        </visual>
        <collision>
           <geometry>
                <cylinder radius="0.05" length="0.04"/>
           </geometry>
        </collision>
        <xacro:inertial_cylinder mass="0.4" length="0.04" radius="0.05">
            <origin xyz="0 0 0" rpy="0 0 0"/>
        </xacro:inertial_cylinder>
    </link>

    <gazebo reference="right_back_wheel">
        <material>
            Gazebo/White
        </material>
        <!--mu1>0.5</mu1-->
        <!--mu2>0.1</mu2-->
    </gazebo>

    <!--Left, Front Wheel Link-->
    <joint name="left_front_wheel_joint" type="continuous">
        <origin xyz="0.1 0.1 0.0" rpy="-${pi/2} 0.0 0.0"/>
        <parent link="base_link"/>
        <child link="left_front_wheel"/>
        <axis xyz="0.0 0.0 1.0"/>
        <limit effort="10000" velocity="1000"/>
        <dynamcis damping="1.0" friction="1.0"/>
    </joint>

    <link name="left_front_wheel">
        <visual>
            <geometry>
                <cylinder radius="0.05" length="0.04"/>
            </geometry>
            <material name="white"/>
        </visual>
        <collision>
           <geometry>
                <cylinder radius="0.05" length="0.04"/>
           </geometry>
        </collision>
        <xacro:inertial_cylinder mass="0.4" length="0.04" radius="0.05">
            <origin xyz="0 0 0" rpy="0 0 0"/>
        </xacro:inertial_cylinder>
    </link>

    <gazebo reference="left_front_wheel">
        <material>
            Gazebo/White
        </material>
        <!--mu1 = 주축 방향 마찰계수, 직진 및 후진에 영향 -->
        <!--mu2 = 주축의 수직 방향 마찰계수, 회전에 영향 -->
        <!--mu1>0.5</mu1-->
        <!--mu2>0.2</mu2-->
    </gazebo>

    <!--Right, Front Wheel Link-->
    <joint name="right_front_wheel_joint" type="continuous">
        <origin xyz="0.1 -0.1 0.0" rpy="-${pi/2} 0.0 0.0"/>
        <parent link="base_link"/>
        <child link="right_front_wheel"/>
        <axis xyz="0.0 0.0 1.0"/>
        <limit effort="10000" velocity="1000"/>
        <dynamcis damping="1.0" friction="1.0"/>
    </joint>

    <link name="right_front_wheel">
        <visual>
            <geometry>
                <cylinder radius="0.05" length="0.04"/>
            </geometry>
            <material name="white"/>
        </visual>
        <collision>
           <geometry>
                <cylinder radius="0.05" length="0.04"/>
           </geometry>
        </collision>
        <xacro:inertial_cylinder mass="0.4" length="0.04" radius="0.05">
            <origin xyz="0 0 0" rpy="0 0 0"/>
        </xacro:inertial_cylinder>
    </link>

    <gazebo reference="right_front_wheel">
        <material>
            Gazebo/White
        </material>
        <!--mu1 = 주축 방향 마찰계수, 직진 및 후진에 영향 -->
        <!--mu2 = 주축의 수직 방향 마찰계수, 회전에 영향 -->
        <!--mu1>0.5</mu1-->
        <!--mu2>0.2</mu2-->
    </gazebo>
</robot>
